<?xml version="1.0"?>
<robot name="hand" xmlns:xacro="http://ros.org/wiki/xacro">

  <material name="blue">
    <color rgba="0 0 0.8 1"/>
  </material>

  <material name="black">
    <color rgba="0 0 0 1"/>
  </material>

  <material name="white">
    <color rgba="1 1 1 1"/>
  </material>

  <xacro:macro name="default_inertial" params="mass">
    <inertial>
      <mass value="${mass}" />
      <inertia ixx="1.0" ixy="0.0" ixz="0.0" iyy="1.0" iyz="0.0" izz="1.0" />
    </inertial>
  </xacro:macro>

  <link name="base_link">
    <visual>
      <geometry>
        <sphere radius="0.5"/>
      </geometry>
      <material name="blue"/>
    </visual>
    <collision>
      <geometry>
        <sphere radius="0.2"/>
      </geometry>
    </collision>
    <xacro:default_inertial mass="1"/>
  </link>

  <link name="arm">
    <visual>
      <origin rpy="0 0 0" xyz="0 0 0.5"/>
      <geometry>
        <cylinder length="1" radius="0.1"/>
      </geometry>
      <material name="black"/>
    </visual>
    <collision>
      <origin rpy="0 0 0" xyz="0 0 0.5"/>
      <geometry>
        <cylinder length="1" radius="0.1"/>
      </geometry>
    </collision>
    <xacro:default_inertial mass="1"/>
  </link>

  <joint name="arm_base" type="revolute">
    <parent link="base_link"/>
    <child link="arm"/>
    <limit effort="1000.0" lower="-0.2" upper="0.2" velocity="0.5"/>
    <origin rpy="0 0 0" xyz="0 0 0"/>
  </joint>

    <link name="hand">
    <visual>
      <origin rpy="0 0 0" xyz="0 0 0"/>
      <geometry>
        <sphere radius="0.2"/>
      </geometry>
      <material name="black"/>
    </visual>
    <collision>
      <origin rpy="0 0 0" xyz="0 0 0"/>
      <geometry>
        <sphere radius="0.2"/>
      </geometry>
    </collision>
    <xacro:default_inertial mass="1"/>
  </link>

  <joint name="hand_arm" type="revolute">
    <parent link="arm"/>
    <child link="hand"/>
    <limit effort="1000.0" lower="-0.2" upper="0.2" velocity="0.5"/>
    <origin rpy="0 0 0" xyz="0 0 1"/>
  </joint>

  <xacro:macro name="finger" params="number offset angle">

    <link name="finger_${number}">
      <visual>
        <origin xyz="0 0 0.1" rpy="${angle} 0 0" />
        <geometry>
          <cylinder radius="0.01" length="0.2"/>
        </geometry>
        <material name="white"/>
      </visual>
      <collision>
        <origin xyz="0 0 0.1" rpy="${angle} 0 0" />
        <geometry>
          <cylinder radius="0.01" length="0.2"/>
        </geometry>
      </collision>
      <xacro:default_inertial mass="1"/>
    </link>
    <joint name="finger_${number}_arm" type="fixed">
      <parent link="hand"/>
      <child link="finger_${number}"/>
      <origin xyz="0 ${offset} 0.1" rpy="0 0 0"/>
    </joint>

  </xacro:macro>

  <xacro:finger number="0" offset= "0"    angle= "0"/>
  <xacro:finger number="1" offset= "-0.1" angle= "0.5"/>
  <xacro:finger number="2" offset= "0.1"  angle= "-0.5"/>

</robot>
